Workbook

Sheet JANEIRO
B1: Fluxo de Caixa 2026 CTR | C1: Janeiro | D1: % ACUMULADO JAN/2026 | E1: % Acum no Ano Comparação | H1: Matriz | I1: Filia Porto | J1: Filia Palmas
A2: Disponíveis Nas Contas Movimento | B2: Disponíveis Nas Contas Movimento inicial | C2: =SUBTOTAL(109,C3:C25) -> 67410.42 | D2: =SUM(D3:D25) -> 1
B3: 1.0 - TESOURARIA MATRIZ PALMAS | C3: 148.53 | D3: =IF(C3=0,"0,00%",C3/$C$2) -> 0.0022033686 | G3: 1
B4: 1.1 - BANCO DO BRASIL C.C.60409-7 MATRIZ | C4: 15268.12 | D4: =IF(C4=0,"0,00%",C4/$C$2) -> 0.22649495 | G4: 2
D5: =IF(C5=0,"0,00%",C5/$C$2) -> 0,00% | G5: 3
B6: 1.2-BRADESCO 15232-3 MATRIZ | C6: 8.62 | D6: =IF(C6=0,"0,00%",C6/$C$2) -> 0.00012787341 | G6: 4
D7: =IF(C7=0,"0,00%",C7/$C$2) -> 0,00% | G7: 5
B8: 1.3 - BANCO STONE MATRIZ C.C 40256726-7 | D8: =IF(C8=0,"0,00%",C8/$C$2) -> 0,00% | G8: 6
B9: 1.4 - BANCO DA AMAZONIA 071730-7 MATRIZ | C9: 124.56 | D9: =IF(C9=0,"0,00%",C9/$C$2) -> 0.0018477856 | G9: 7
B10: 1.4.1.INVESTIMENTO CDBORE RCP TXFL | D10: =IF(C10=0,"0,00%",C10/$C$2) -> 0,00% | G10: 8
B11: 1.5 - ITAU C.C.98671-6 MATRIZ | C11: 40443.69 | D11: =IF(C11=0,"0,00%",C11/$C$2) -> 0.59996199 | G11: 9
B12: 1.5.03. ITAU C.C 83290-2 GARANTIDA | C12: 902.73 | D12: =IF(C12=0,"0,00%",C12/$C$2) -> 0.01339155 | G12: 10
B13: 1.9 - CONTA PERDA/ROUBO/BONIFICAÇÃO E DOAÇÃO | C13: 0 | D13: =IF(C13=0,"0,00%",C13/$C$2) -> 0,00% | G13: 11
D14: =IF(C14=0,"0,00%",C14/$C$2) -> 0,00% | G14: 12
B15: 2.1 - BANCO DO BRASIL C.C.60638-3 FILIAL PALMAS | C15: 1415.61 | D15: =IF(C15=0,"0,00%",C15/$C$2) -> 0.020999869 | G15: 13
D16: =IF(C16=0,"0,00%",C16/$C$2) -> 0,00% | E16: =#REF! -> #REF! | G16: 14
D17: =IF(C17=0,"0,00%",C17/$C$2) -> 0,00% | E17: =#REF! -> #REF! | G17: 15
B18: 2.4 - ITAU C.C.98669-0 FILIAL PALMAS | C18: 536.72 | D18: =IF(C18=0,"0,00%",C18/$C$2) -> 0.0079619738 | E18: =#REF! -> #REF! | G18: 16
B19: 2.9 - CONTA PERDA/ROUBO E BONIFICAÇÃO FILIAL | C19: 0 | D19: =IF(C19=0,"0,00%",C19/$C$2) -> 0,00% | E19: =#REF! -> #REF! | G19: 17
B20: 4.0 - TESOURARIA FILIAL PORTO | C20: 1409.97 | D20: =IF(C20=0,"0,00%",C20/$C$2) -> 0.020916203 | E20: =#REF! -> #REF! | G20: 18
B21: 4.1 - BANCO DO BRASIL C.C.61105-0 FILIAL PORTO | C21: 57.34 | D21: =IF(C21=0,"0,00%",C21/$C$2) -> 0.00085061034 | E21: =#REF! -> #REF! | G21: 19
D22: =IF(C22=0,"0,00%",C22/$C$2) -> 0,00% | E22: =#REF! -> #REF! | G22: 20
B23: 4.4 - MERCADO PAGO PIX FILIAL PORTO | C23: 5412.19 | D23: =IF(C23=0,"0,00%",C23/$C$2) -> 0.080287143 | E23: =#REF! -> #REF! | G23: 21
B24: 4.9 - CONTA PERDA/ROUBO E BONIFICAÇÃO FILIAL | C24: 0 | D24: =IF(C24=0,"0,00%",C24/$C$2) -> 0,00% | G24: 22
B25: 91.CARTÃO ENDERED 5099+4596+6933+8072 - ESCRITORIO | C25: 1682.34 | D25: =IF(C25=0,"0,00%",C25/$C$2) -> 0.024956676 | G25: 23
D26: =IF(C26=0,"0,00%",C26/$C$2) -> 0,00% | E26: =#REF! -> #REF! | G26: 24
B27: Total Receitas Operacionais / Vendas | C27: =SUBTOTAL(109,C29:C51) -> 749632.93 | D27: =IFERROR(C27/C332,"") -> 0.99826619 | E27: 0.88526119 | H27: =H28+I28 -> 284105.37
A28: 1.1. Receita com Vendas | B28: 1.1. Receita com Vendas | C28: =SUBTOTAL(109,C29:C47) -> 749632.93 | D28: =SUM(D29:D47) -> 0.99826619 | E28: 0.88251933 | H28: =SUM(H29:H36) -> 42578.96 | I28: =SUM(I29:I36) -> 241526.41 | J28: =SUM(J29:J36) -> 465527.56
B29: 1.1.01. Receita em Dinheiro | C29: =H29+I29+J29 -> 2199.78 | D29: =IF(C29=0,"0,00%",C29/$C$332) -> 0.0029293884 | E29: 0.079252981 | F29: =IF(Fluxo_de_Caixa_Janeiro34591171012151619[[#This Row],[% ACUMULADO DEZ/2026]]>=Fluxo_de_Caixa_Janeiro34591171012151619[[#This Row],[% Acum no Ano Comparação]],"Verd","Fals") -> Verd | I29: =3454.6-2223.58 -> 1231.02 | J29: 968.76
B30: 1.1.01. Receita em Cartão (Crédito e Débito) | C30: =H30+I30+J30 -> 328505.72 | D30: =IF(C30=0,"0,00%",C30/$C$332) -> 0.43746231 | E30: 0.092740536 | F30: =IF(Fluxo_de_Caixa_Janeiro34591171012151619[[#This Row],[% ACUMULADO DEZ/2026]]>=Fluxo_de_Caixa_Janeiro34591171012151619[[#This Row],[% Acum no Ano Comparação]],"Verd","Fals") -> Verd | G30: =C361 -> -150.01 | H30: 6947.26 | I30: 61647.12 | J30: 259911.34
B31: 1.1.01. Receita de Cheque A Vista | C31: =H31+I31+J31 -> 15000 | D31: =IF(C31=0,"0,00%",C31/$C$332) -> 0.0199751 | E31: 0.00028628486 | F31: =IF(Fluxo_de_Caixa_Janeiro34591171012151619[[#This Row],[% ACUMULADO DEZ/2026]]>=Fluxo_de_Caixa_Janeiro34591171012151619[[#This Row],[% Acum no Ano Comparação]],"Verd","Fals") -> Verd | I31: 15000
B32: 1.1.01. Receita de Cheque Pré | C32: =H32+I32+J32 -> 0 | D32: =IF(C32=0,"0,00%",C32/$C$332) -> 0,00% | E32: 0.0063111634 | F32: =IF(Fluxo_de_Caixa_Janeiro34591171012151619[[#This Row],[% ACUMULADO DEZ/2026]]>=Fluxo_de_Caixa_Janeiro34591171012151619[[#This Row],[% Acum no Ano Comparação]],"Verd","Fals") -> Verd
B33: 1.1.01. Recebimento de Carteira (Notinha) | C33: =H33+I33+J33 -> 0 | D33: =IF(C33=0,"0,00%",C33/$C$332) -> 0,00% | E33: 0.0001318638 | F33: =IF(Fluxo_de_Caixa_Janeiro34591171012151619[[#This Row],[% ACUMULADO DEZ/2026]]>=Fluxo_de_Caixa_Janeiro34591171012151619[[#This Row],[% Acum no Ano Comparação]],"Verd","Fals") -> Verd
B34: 1.1.01. Recebimento de Boletos | C34: =H34+I34+J34 -> 144411.43 | D34: =IF(C34=0,"0,00%",C34/$C$332) -> 0.19230885 | E34: 0.66745712 | F34: =IF(Fluxo_de_Caixa_Janeiro34591171012151619[[#This Row],[% ACUMULADO DEZ/2026]]>=Fluxo_de_Caixa_Janeiro34591171012151619[[#This Row],[% Acum no Ano Comparação]],"Verd","Fals") -> Verd | H34: 10372.54 | I34: 46325.81 | J34: 87713.08
B35: 1.1.01. Recebimento em Depósito e Dep. PIX | C35: =H35+I35+J35 -> 259516 | D35: =IF(C35=0,"0,00%",C35/$C$332) -> 0.34559054 | E35: 0.036171198 | F35: =IF(Fluxo_de_Caixa_Janeiro34591171012151619[[#This Row],[% ACUMULADO DEZ/2026]]>=Fluxo_de_Caixa_Janeiro34591171012151619[[#This Row],[% Acum no Ano Comparação]],"Verd","Fals") -> Verd | H35: 25259.16 | I35: 117322.46 | J35: 116934.38
B36: 1.1.02. Recebimento Cheque Devolvido | C36: =H36+I36+J36 -> 0 | D36: =IF(C36=0,"0,00%",C36/$C$332) -> 0,00% | E36: 0.00016817802 | F36: =IF(Fluxo_de_Caixa_Janeiro34591171012151619[[#This Row],[% ACUMULADO DEZ/2026]]>=Fluxo_de_Caixa_Janeiro34591171012151619[[#This Row],[% Acum no Ano Comparação]],"Verd","Fals") -> Verd
D37: =IF(C37=0,"0,00%",C37/$C$332) -> 0,00% | E37: =#REF! -> #REF! | F37: =IF(Fluxo_de_Caixa_Janeiro34591171012151619[[#This Row],[% ACUMULADO DEZ/2026]]>=Fluxo_de_Caixa_Janeiro34591171012151619[[#This Row],[% Acum no Ano Comparação]],"Verd","Fals") -> #REF!
D38: =IF(C38=0,"0,00%",C38/$C$332) -> 0,00% | E38: =#REF! -> #REF! | F38: =IF(Fluxo_de_Caixa_Janeiro34591171012151619[[#This Row],[% ACUMULADO DEZ/2026]]>=Fluxo_de_Caixa_Janeiro34591171012151619[[#This Row],[% Acum no Ano Comparação]],"Verd","Fals") -> #REF!
D39: =IF(C39=0,"0,00%",C39/$C$332) -> 0,00% | E39: =#REF! -> #REF! | F39: =IF(Fluxo_de_Caixa_Janeiro34591171012151619[[#This Row],[% ACUMULADO DEZ/2026]]>=Fluxo_de_Caixa_Janeiro34591171012151619[[#This Row],[% Acum no Ano Comparação]],"Verd","Fals") -> #REF!
D40: =IF(C40=0,"0,00%",C40/$C$332) -> 0,00% | E40: =#REF! -> #REF! | F40: =IF(Fluxo_de_Caixa_Janeiro34591171012151619[[#This Row],[% ACUMULADO DEZ/2026]]>=Fluxo_de_Caixa_Janeiro34591171012151619[[#This Row],[% Acum no Ano Comparação]],"Verd","Fals") -> #REF!
...

Sheet FEVEREIRO
B1: Fluxo de Caixa 2026 CTR | C1: Fevereiro | D1: % ACUMULADO FEV/2026 | E1: % Acum no Ano Comparação | H1: Matriz | I1: Filia Porto | J1: Filia Palmas
A2: Disponíveis Nas Contas Movimento | B2: =Fluxo_de_Caixa_Janeiro[[#This Row],[Fluxo de Caixa 2026 CTR]] -> Disponíveis Nas Contas Movimento inicial | C2: =SUBTOTAL(109,C3:C26) -> 31847.63 | D2: =SUM(D3:D26) -> 0.99476131
B3: =Fluxo_de_Caixa_Janeiro[[#This Row],[Fluxo de Caixa 2026 CTR]] -> 1.0 - TESOURARIA MATRIZ PALMAS | C3: =JANEIRO!C337 -> 40.53 | D3: =IF(C3=0,"0,00%",C3/$C$2) -> 0.0012726222
B4: =Fluxo_de_Caixa_Janeiro[[#This Row],[Fluxo de Caixa 2026 CTR]] -> 1.1 - BANCO DO BRASIL C.C.60409-7 MATRIZ | C4: =JANEIRO!C338 -> 108.85 | D4: =IF(C4=0,"0,00%",C4/$C$2) -> 0.0034178367
B5: =Fluxo_de_Caixa_Janeiro[[#This Row],[Fluxo de Caixa 2026 CTR]] -> 0 | C5: =JANEIRO!C339 -> 0 | D5: =IF(C5=0,"0,00%",C5/$C$2) -> 0,00%
B6: =Fluxo_de_Caixa_Janeiro[[#This Row],[Fluxo de Caixa 2026 CTR]] -> 1.2-BRADESCO 15232-3 MATRIZ | C6: =JANEIRO!C340 -> 3332.91 | D6: =IF(C6=0,"0,00%",C6/$C$2) -> 0.10465174
B7: =Fluxo_de_Caixa_Janeiro[[#This Row],[Fluxo de Caixa 2026 CTR]] -> 0 | C7: =JANEIRO!C341 -> 0 | D7: =IF(C7=0,"0,00%",C7/$C$2) -> 0,00%
B8: =Fluxo_de_Caixa_Janeiro[[#This Row],[Fluxo de Caixa 2026 CTR]] -> 1.3 - BANCO STONE MATRIZ C.C 40256726-7 | C8: =JANEIRO!C342 -> 2671 | D8: =IF(C8=0,"0,00%",C8/$C$2) -> 0.083868093 | E8: =#REF! -> #REF!
B9: =Fluxo_de_Caixa_Janeiro[[#This Row],[Fluxo de Caixa 2026 CTR]] -> 1.4 - BANCO DA AMAZONIA 071730-7 MATRIZ | C9: =JANEIRO!C343 -> 281.78 | D9: =IF(C9=0,"0,00%",C9/$C$2) -> 0.0088477541 | E9: =#REF! -> #REF!
B10: =Fluxo_de_Caixa_Janeiro[[#This Row],[Fluxo de Caixa 2026 CTR]] -> 1.4.1.INVESTIMENTO CDBORE RCP TXFL | C10: =JANEIRO!C344 -> 0 | D10: =IF(C10=0,"0,00%",C10/$C$2) -> 0,00% | E10: =#REF! -> #REF!
B11: =Fluxo_de_Caixa_Janeiro[[#This Row],[Fluxo de Caixa 2026 CTR]] -> 1.5 - ITAU C.C.98671-6 MATRIZ | C11: =JANEIRO!C345 -> 18153.73 | D11: =IF(C11=0,"0,00%",C11/$C$2) -> 0.57001824 | E11: =#REF! -> #REF!
B12: =Fluxo_de_Caixa_Janeiro[[#This Row],[Fluxo de Caixa 2026 CTR]] -> 1.5.03. ITAU C.C 83290-2 GARANTIDA | C12: =JANEIRO!C346 -> 1286.28 | D12: =IF(C12=0,"0,00%",C12/$C$2) -> 0.040388563 | E12: =#REF! -> #REF!
B13: =Fluxo_de_Caixa_Janeiro[[#This Row],[Fluxo de Caixa 2026 CTR]] -> 1.9 - CONTA PERDA/ROUBO/BONIFICAÇÃO E DOAÇÃO | C13: =JANEIRO!C347 -> 0 | D13: =IF(C13=0,"0,00%",C13/$C$2) -> 0,00%
B14: =Fluxo_de_Caixa_Janeiro[[#This Row],[Fluxo de Caixa 2026 CTR]] -> 0 | C14: =JANEIRO!C348 -> 0 | D14: =IF(C14=0,"0,00%",C14/$C$2) -> 0,00%
B15: =Fluxo_de_Caixa_Janeiro[[#This Row],[Fluxo de Caixa 2026 CTR]] -> 2.1 - BANCO DO BRASIL C.C.60638-3 FILIAL PALMAS | C15: =JANEIRO!C349 -> 1829.48 | D15: =IF(C15=0,"0,00%",C15/$C$2) -> 0.057444777
B16: =Fluxo_de_Caixa_Janeiro[[#This Row],[Fluxo de Caixa 2026 CTR]] -> 0 | C16: =JANEIRO!C350 -> 0 | D16: =IF(C16=0,"0,00%",C16/$C$2) -> 0,00%
B17: =Fluxo_de_Caixa_Janeiro[[#This Row],[Fluxo de Caixa 2026 CTR]] -> 0 | C17: =JANEIRO!C351 -> 0 | D17: =IF(C17=0,"0,00%",C17/$C$2) -> 0,00%
B18: =Fluxo_de_Caixa_Janeiro[[#This Row],[Fluxo de Caixa 2026 CTR]] -> 2.4 - ITAU C.C.98669-0 FILIAL PALMAS | C18: =JANEIRO!C352 -> 536.72 | D18: =IF(C18=0,"0,00%",C18/$C$2) -> 0.016852745
B19: =Fluxo_de_Caixa_Janeiro[[#This Row],[Fluxo de Caixa 2026 CTR]] -> 2.9 - CONTA PERDA/ROUBO E BONIFICAÇÃO FILIAL | C19: =JANEIRO!C353 -> -219.15 | D19: =IF(C19=0,"0,00%",C19/$C$2) -> -0.0068812028
B20: =Fluxo_de_Caixa_Janeiro[[#This Row],[Fluxo de Caixa 2026 CTR]] -> 4.0 - TESOURARIA FILIAL PORTO | C20: =JANEIRO!C354 -> 385.51 | D20: =IF(C20=0,"0,00%",C20/$C$2) -> 0.012104825
B21: =Fluxo_de_Caixa_Janeiro[[#This Row],[Fluxo de Caixa 2026 CTR]] -> 4.1 - BANCO DO BRASIL C.C.61105-0 FILIAL PORTO | C21: =JANEIRO!C355 -> 16.83 | E21: =#REF! -> #REF!
B22: =Fluxo_de_Caixa_Janeiro[[#This Row],[Fluxo de Caixa 2026 CTR]] -> 0 | C22: =JANEIRO!C356 -> 0 | E22: =#REF! -> #REF!
B23: =Fluxo_de_Caixa_Janeiro[[#This Row],[Fluxo de Caixa 2026 CTR]] -> 4.4 - MERCADO PAGO PIX FILIAL PORTO | C23: =JANEIRO!C357 -> 2060.42 | D23: =IF(C23=0,"0,00%",C23/$C$2) -> 0.06469618
B24: =Fluxo_de_Caixa_Janeiro[[#This Row],[Fluxo de Caixa 2026 CTR]] -> 4.9 - CONTA PERDA/ROUBO E BONIFICAÇÃO FILIAL | C24: =JANEIRO!C358 -> 0 | E24: =#REF! -> #REF!
B25: =Fluxo_de_Caixa_Janeiro[[#This Row],[Fluxo de Caixa 2026 CTR]] -> 91.CARTÃO ENDERED 5099+4596+6933+8072 - ESCRITORIO | C25: =JANEIRO!C359 -> 1362.74 | D25: =IF(C25=0,"0,00%",C25/$C$2) -> 0.042789369 | E25: =#REF! -> #REF!
B26: =Fluxo_de_Caixa_Janeiro[[#This Row],[Fluxo de Caixa 2026 CTR]] -> 0 | C26: =JANEIRO!C361 -> -150.01 | D26: =IF(C26=0,"0,00%",C26/$C$2) -> -0.0047102406 | G26: 24
B27: =Fluxo_de_Caixa_Janeiro[[#This Row],[Fluxo de Caixa 2026 CTR]] -> Total Receitas Operacionais / Vendas | C27: =SUBTOTAL(109,C29:C51) -> 1038589.1 | D27: =IFERROR(C27/C332,"") -> 0.99992917 | E27: 0.88526119 | H27: =H28+I28 -> 560226.19
A28: 1.1. Receita com Vendas | B28: =Fluxo_de_Caixa_Janeiro[[#This Row],[Fluxo de Caixa 2026 CTR]] -> 1.1. Receita com Vendas | C28: =SUBTOTAL(109,C29:C47) -> 1038589.1 | D28: =SUM(D29:D47) -> 0.99992917 | E28: 0.88251933 | H28: =SUM(H29:H36) -> 37065.49 | I28: =SUM(I29:I36) -> 523160.7 | J28: =SUM(J29:J36) -> 478362.9
B29: =Fluxo_de_Caixa_Janeiro[[#This Row],[Fluxo de Caixa 2026 CTR]] -> 1.1.01. Receita em Dinheiro | C29: =H29+I29+J29 -> 4660.37 | D29: =IF(C29=0,"0,00%",C29/$C$332) -> 0.0044868947 | E29: 0.079252981 | F29: =IF(Fluxo_de_Caixa_Janeiro34591171012151619[[#This Row],[% ACUMULADO DEZ/2026]]>=Fluxo_de_Caixa_Janeiro34591171012151619[[#This Row],[% Acum no Ano Comparação]],"Verd","Fals") -> Verd | H29: 135.61 | I29: 3436.01 | J29: 1088.75
B30: =Fluxo_de_Caixa_Janeiro[[#This Row],[Fluxo de Caixa 2026 CTR]] -> 1.1.01. Receita em Cartão (Crédito e Débito) | C30: =H30+I30+J30 -> 221053.51 | D30: =IF(C30=0,"0,00%",C30/$C$332) -> 0.21282512 | E30: 0.092740536 | F30: =IF(Fluxo_de_Caixa_Janeiro34591171012151619[[#This Row],[% ACUMULADO DEZ/2026]]>=Fluxo_de_Caixa_Janeiro34591171012151619[[#This Row],[% Acum no Ano Comparação]],"Verd","Fals") -> Verd | H30: 7056.17 | I30: 134559.92 | J30: 79437.42
B31: =Fluxo_de_Caixa_Janeiro[[#This Row],[Fluxo de Caixa 2026 CTR]] -> 1.1.01. Receita de Cheque A Vista | C31: =H31+I31+J31 -> 26907.75 | D31: =IF(C31=0,"0,00%",C31/$C$332) -> 0.025906149 | E31: 0.00028628486 | F31: =IF(Fluxo_de_Caixa_Janeiro34591171012151619[[#This Row],[% ACUMULADO DEZ/2026]]>=Fluxo_de_Caixa_Janeiro34591171012151619[[#This Row],[% Acum no Ano Comparação]],"Verd","Fals") -> Verd | I31: 26907.75
B32: =Fluxo_de_Caixa_Janeiro[[#This Row],[Fluxo de Caixa 2026 CTR]] -> 1.1.01. Receita de Cheque Pré | C32: =H32+I32+J32 -> 0 | D32: =IF(C32=0,"0,00%",C32/$C$332) -> 0,00% | E32: 0.0063111634 | F32: =IF(Fluxo_de_Caixa_Janeiro34591171012151619[[#This Row],[% ACUMULADO DEZ/2026]]>=Fluxo_de_Caixa_Janeiro34591171012151619[[#This Row],[% Acum no Ano Comparação]],"Verd","Fals") -> Verd | G32: =C361 -> 180.01
B33: =Fluxo_de_Caixa_Janeiro[[#This Row],[Fluxo de Caixa 2026 CTR]] -> 1.1.01. Recebimento de Carteira (Notinha) | C33: =H33+I33+J33 -> 0 | D33: =IF(C33=0,"0,00%",C33/$C$332) -> 0,00% | E33: 0.0001318638 | F33: =IF(Fluxo_de_Caixa_Janeiro34591171012151619[[#This Row],[% ACUMULADO DEZ/2026]]>=Fluxo_de_Caixa_Janeiro34591171012151619[[#This Row],[% Acum no Ano Comparação]],"Verd","Fals") -> Verd
B34: =Fluxo_de_Caixa_Janeiro[[#This Row],[Fluxo de Caixa 2026 CTR]] -> 1.1.01. Recebimento de Boletos | C34: =H34+I34+J34 -> 317162.15 | D34: =IF(C34=0,"0,00%",C34/$C$332) -> 0.30535626 | E34: 0.66745712 | F34: =IF(Fluxo_de_Caixa_Janeiro34591171012151619[[#This Row],[% ACUMULADO DEZ/2026]]>=Fluxo_de_Caixa_Janeiro34591171012151619[[#This Row],[% Acum no Ano Comparação]],"Verd","Fals") -> Verd | H34: 22534.42 | I34: =94826.7+10161.81 -> 104988.51 | J34: 189639.22
B35: =Fluxo_de_Caixa_Janeiro[[#This Row],[Fluxo de Caixa 2026 CTR]] -> 1.1.01. Recebimento em Depósito e Dep. PIX | C35: =H35+I35+J35 -> 468805.31 | D35: =IF(C35=0,"0,00%",C35/$C$332) -> 0.45135474 | E35: 0.036171198 | F35: =IF(Fluxo_de_Caixa_Janeiro34591171012151619[[#This Row],[% ACUMULADO DEZ/2026]]>=Fluxo_de_Caixa_Janeiro34591171012151619[[#This Row],[% Acum no Ano Comparação]],"Verd","Fals") -> Verd | H35: 7339.29 | I35: 253268.51 | J35: 208197.51
B36: =Fluxo_de_Caixa_Janeiro[[#This Row],[Fluxo de Caixa 2026 CTR]] -> 1.1.02. Recebimento Cheque Devolvido | C36: =H36+I36+J36 -> 0 | D36: =IF(C36=0,"0,00%",C36/$C$332) -> 0,00% | E36: 0.00016817802 | F36: =IF(Fluxo_de_Caixa_Janeiro34591171012151619[[#This Row],[% ACUMULADO DEZ/2026]]>=Fluxo_de_Caixa_Janeiro34591171012151619[[#This Row],[% Acum no Ano Comparação]],"Verd","Fals") -> Verd
B37: =Fluxo_de_Caixa_Janeiro[[#This Row],[Fluxo de Caixa 2026 CTR]] -> 0 | D37: =IF(C37=0,"0,00%",C37/$C$332) -> 0,00% | E37: =#REF! -> #REF! | F37: =IF(Fluxo_de_Caixa_Janeiro34591171012151619[[#This Row],[% ACUMULADO DEZ/2026]]>=Fluxo_de_Caixa_Janeiro34591171012151619[[#This Row],[% Acum no Ano Comparação]],"Verd","Fals") -> #REF!
B38: =Fluxo_de_Caixa_Janeiro[[#This Row],[Fluxo de Caixa 2026 CTR]] -> 0 | D38: =IF(C38=0,"0,00%",C38/$C$332) -> 0,00% | E38: =#REF! -> #REF! | F38: =IF(Fluxo_de_Caixa_Janeiro34591171012151619[[#This Row],[% ACUMULADO DEZ/2026]]>=Fluxo_de_Caixa_Janeiro34591171012151619[[#This Row],[% Acum no Ano Comparação]],"Verd","Fals") -> #REF!
B39: =Fluxo_de_Caixa_Janeiro[[#This Row],[Fluxo de Caixa 2026 CTR]] -> 0 | D39: =IF(C39=0,"0,00%",C39/$C$332) -> 0,00% | E39: =#REF! -> #REF! | F39: =IF(Fluxo_de_Caixa_Janeiro34591171012151619[[#This Row],[% ACUMULADO DEZ/2026]]>=Fluxo_de_Caixa_Janeiro34591171012151619[[#This Row],[% Acum no Ano Comparação]],"Verd","Fals") -> #REF!
B40: =Fluxo_de_Caixa_Janeiro[[#This Row],[Fluxo de Caixa 2026 CTR]] -> 0 | D40: =IF(C40=0,"0,00%",C40/$C$332) -> 0,00% | E40: =#REF! -> #REF! | F40: =IF(Fluxo_de_Caixa_Janeiro34591171012151619[[#This Row],[% ACUMULADO DEZ/2026]]>=Fluxo_de_Caixa_Janeiro34591171012151619[[#This Row],[% Acum no Ano Comparação]],"Verd","Fals") -> #REF!
...

Sheet MARÇO
B1: Fluxo de Caixa 2026 CTR | C1: Março | D1: % ACUMULADO MAR/2026 | E1: % Acum no Ano Comparação | H1: Matriz | I1: Filia Porto | J1: Filia Palmas
A2: Disponíveis Nas Contas Movimento | B2: =Fluxo_de_Caixa_Janeiro[[#This Row],[Fluxo de Caixa 2026 CTR]] -> Disponíveis Nas Contas Movimento inicial | C2: =SUBTOTAL(109,C3:C26) -> 8957.59 | D2: =SUM(D3:D26) -> 1
B3: =Fluxo_de_Caixa_Janeiro[[#This Row],[Fluxo de Caixa 2026 CTR]] -> 1.0 - TESOURARIA MATRIZ PALMAS | C3: =FEVEREIRO!C337 -> 337.58 | D3: =IF(C3=0,"0,00%",C3/$C$2) -> 0.037686476 | G3: 1
B4: =Fluxo_de_Caixa_Janeiro[[#This Row],[Fluxo de Caixa 2026 CTR]] -> 1.1 - BANCO DO BRASIL C.C.60409-7 MATRIZ | C4: =FEVEREIRO!C338 -> 55.77 | D4: =IF(C4=0,"0,00%",C4/$C$2) -> 0.006226005 | E4: =#REF! -> #REF! | G4: 2
B5: =Fluxo_de_Caixa_Janeiro[[#This Row],[Fluxo de Caixa 2026 CTR]] -> 0 | C5: =FEVEREIRO!C339 -> 0 | D5: =IF(C5=0,"0,00%",C5/$C$2) -> 0,00% | E5: =#REF! -> #REF! | G5: 3
B6: =Fluxo_de_Caixa_Janeiro[[#This Row],[Fluxo de Caixa 2026 CTR]] -> 1.2-BRADESCO 15232-3 MATRIZ | C6: =FEVEREIRO!C340 -> 25.97 | D6: =IF(C6=0,"0,00%",C6/$C$2) -> 0.0028992173 | E6: =#REF! -> #REF! | G6: 3
B7: =Fluxo_de_Caixa_Janeiro[[#This Row],[Fluxo de Caixa 2026 CTR]] -> 0 | C7: =FEVEREIRO!C341 -> 0 | D7: =IF(C7=0,"0,00%",C7/$C$2) -> 0,00% | E7: =#REF! -> #REF! | G7: 5
B8: =Fluxo_de_Caixa_Janeiro[[#This Row],[Fluxo de Caixa 2026 CTR]] -> 1.3 - BANCO STONE MATRIZ C.C 40256726-7 | C8: =FEVEREIRO!C342 -> 0 | D8: =IF(C8=0,"0,00%",C8/$C$2) -> 0,00% | E8: =#REF! -> #REF! | G8: 4
B9: =Fluxo_de_Caixa_Janeiro[[#This Row],[Fluxo de Caixa 2026 CTR]] -> 1.4 - BANCO DA AMAZONIA 071730-7 MATRIZ | C9: =FEVEREIRO!C343 -> 1900.51 | D9: =IF(C9=0,"0,00%",C9/$C$2) -> 0.21216756 | E9: =#REF! -> #REF! | G9: 7
B10: =Fluxo_de_Caixa_Janeiro[[#This Row],[Fluxo de Caixa 2026 CTR]] -> 1.4.1.INVESTIMENTO CDBORE RCP TXFL | C10: =FEVEREIRO!C344 -> 0 | D10: =IF(C10=0,"0,00%",C10/$C$2) -> 0,00% | E10: =#REF! -> #REF! | G10: 5
B11: =Fluxo_de_Caixa_Janeiro[[#This Row],[Fluxo de Caixa 2026 CTR]] -> 1.5 - ITAU C.C.98671-6 MATRIZ | C11: =FEVEREIRO!C345 -> 33831.3 | D11: =IF(C11=0,"0,00%",C11/$C$2) -> 3.7768306 | E11: =#REF! -> #REF! | G11: 6
B12: =Fluxo_de_Caixa_Janeiro[[#This Row],[Fluxo de Caixa 2026 CTR]] -> 1.5.03. ITAU C.C 83290-2 GARANTIDA | C12: =FEVEREIRO!C346 -> 5399.76 | D12: =IF(C12=0,"0,00%",C12/$C$2) -> 0.60281393 | E12: =#REF! -> #REF! | G12: 7
B13: =Fluxo_de_Caixa_Janeiro[[#This Row],[Fluxo de Caixa 2026 CTR]] -> 1.9 - CONTA PERDA/ROUBO/BONIFICAÇÃO E DOAÇÃO | C13: =FEVEREIRO!C347 -> -20953.13 | D13: =IF(C13=0,"0,00%",C13/$C$2) -> -2.3391481 | G13: 8
B14: =Fluxo_de_Caixa_Janeiro[[#This Row],[Fluxo de Caixa 2026 CTR]] -> 0 | C14: =FEVEREIRO!C348 -> 0 | D14: =IF(C14=0,"0,00%",C14/$C$2) -> 0,00% | G14: 12
B15: =Fluxo_de_Caixa_Janeiro[[#This Row],[Fluxo de Caixa 2026 CTR]] -> 2.1 - BANCO DO BRASIL C.C.60638-3 FILIAL PALMAS | C15: =FEVEREIRO!C349 -> 65.56 | D15: =IF(C15=0,"0,00%",C15/$C$2) -> 0.0073189329 | G15: 9
B16: =Fluxo_de_Caixa_Janeiro[[#This Row],[Fluxo de Caixa 2026 CTR]] -> 0 | C16: =FEVEREIRO!C350 -> 0 | D16: =IF(C16=0,"0,00%",C16/$C$2) -> 0,00% | G16: 14
B17: =Fluxo_de_Caixa_Janeiro[[#This Row],[Fluxo de Caixa 2026 CTR]] -> 0 | C17: =FEVEREIRO!C351 -> 0 | D17: =IF(C17=0,"0,00%",C17/$C$2) -> 0,00% | G17: 15
B18: =Fluxo_de_Caixa_Janeiro[[#This Row],[Fluxo de Caixa 2026 CTR]] -> 2.4 - ITAU C.C.98669-0 FILIAL PALMAS | C18: =FEVEREIRO!C352 -> 37.73 | D18: =IF(C18=0,"0,00%",C18/$C$2) -> 0.0042120704 | G18: 10
B19: =Fluxo_de_Caixa_Janeiro[[#This Row],[Fluxo de Caixa 2026 CTR]] -> 2.9 - CONTA PERDA/ROUBO E BONIFICAÇÃO FILIAL | C19: =FEVEREIRO!C353 -> -8598.58 | D19: =IF(C19=0,"0,00%",C19/$C$2) -> -0.95992114 | G19: 11
B20: =Fluxo_de_Caixa_Janeiro[[#This Row],[Fluxo de Caixa 2026 CTR]] -> 4.0 - TESOURARIA FILIAL PORTO | C20: =FEVEREIRO!C354 -> 1327.43 | D20: =IF(C20=0,"0,00%",C20/$C$2) -> 0.14819053 | G20: 12
B21: =Fluxo_de_Caixa_Janeiro[[#This Row],[Fluxo de Caixa 2026 CTR]] -> 4.1 - BANCO DO BRASIL C.C.61105-0 FILIAL PORTO | C21: =FEVEREIRO!C355 -> 111.93 | D21: =IF(C21=0,"0,00%",C21/$C$2) -> 0.012495548 | G21: 13
B22: =Fluxo_de_Caixa_Janeiro[[#This Row],[Fluxo de Caixa 2026 CTR]] -> 0 | C22: =FEVEREIRO!C356 -> 0 | D22: =IF(C22=0,"0,00%",C22/$C$2) -> 0,00% | G22: 20
B23: =Fluxo_de_Caixa_Janeiro[[#This Row],[Fluxo de Caixa 2026 CTR]] -> 4.4 - MERCADO PAGO PIX FILIAL PORTO | C23: =FEVEREIRO!C357 -> 22539.57 | D23: =IF(C23=0,"0,00%",C23/$C$2) -> 2.5162538 | G23: 14
B24: =Fluxo_de_Caixa_Janeiro[[#This Row],[Fluxo de Caixa 2026 CTR]] -> 4.9 - CONTA PERDA/ROUBO E BONIFICAÇÃO FILIAL | C24: =FEVEREIRO!C358 -> -29071.86 | D24: =IF(C24=0,"0,00%",C24/$C$2) -> -3.2455002 | G24: 15
... B26: =Fluxo_de_Caixa_Janeiro[[#This Row],[Fluxo de Caixa 2026 CTR]] -> 0 | C26: =FEVEREIRO!C360 -> 0 | D26: =IF(C26=0,"0,00%",C26/$C$2) -> 0,00% | G26: 24
B27: =Fluxo_de_Caixa_Janeiro[[#This Row],[Fluxo de Caixa 2026 CTR]] -> Total Receitas Operacionais / Vendas | C27: =SUBTOTAL(109,C29:C51) -> 1087750 | D27: =IFERROR(C27/C332,"") -> 0.56707334 | E27: 0.88526119 | H27: =H28+I28 -> 516141.03
A28: 1.1. Receita com Vendas | B28: =Fluxo_de_Caixa_Janeiro[[#This Row],[Fluxo de Caixa 2026 CTR]] -> 1.1. Receita com Vendas | C28: =SUBTOTAL(109,C29:C47) -> 1087750 | D28: =SUM(D29:D47) -> 0.56707334 | E28: 0.88251933 | H28: =SUM(H29:H36) -> 47356.86 | I28: =SUM(I29:I36) -> 468784.17 | J28: =SUM(J29:J36) -> 571608.96
B29: =Fluxo_de_Caixa_Janeiro[[#This Row],[Fluxo de Caixa 2026 CTR]] -> 1.1.01. Receita em Dinheiro | C29: =H29+I29+J29 -> 2754.35 | D29: =IF(C29=0,"0,00%",C29/$C$332) -> 0.0014359168 | E29: 0.079252981 | F29: =IF(Fluxo_de_Caixa_Janeiro34591171012151619[[#This Row],[% ACUMULADO DEZ/2026]]>=Fluxo_de_Caixa_Janeiro34591171012151619[[#This Row],[% Acum no Ano Comparação]],"Verd","Fals") -> Verd | H29: 0 | I29: 2262.35 | J29: 492
B30: =Fluxo_de_Caixa_Janeiro[[#This Row],[Fluxo de Caixa 2026 CTR]] -> 1.1.01. Receita em Cartão (Crédito e Débito) | C30: =H30+I30+J30 -> 110371.17 | D30: =IF(C30=0,"0,00%",C30/$C$332) -> 0.057539461 | E30: 0.092740536 | F30: =IF(Fluxo_de_Caixa_Janeiro34591171012151619[[#This Row],[% ACUMULADO DEZ/2026]]>=Fluxo_de_Caixa_Janeiro34591171012151619[[#This Row],[% Acum no Ano Comparação]],"Verd","Fals") -> Verd | H30: 22.79 | I30: 41662.34 | J30: 68686.04
B31: =Fluxo_de_Caixa_Janeiro[[#This Row],[Fluxo de Caixa 2026 CTR]] -> 1.1.01. Receita de Cheque A Vista | C31: =H31+I31+J31 -> 0 | D31: =IF(C31=0,"0,00%",C31/$C$332) -> 0,00% | E31: 0.00028628486 | F31: =IF(Fluxo_de_Caixa_Janeiro34591171012151619[[#This Row],[% ACUMULADO DEZ/2026]]>=Fluxo_de_Caixa_Janeiro34591171012151619[[#This Row],[% Acum no Ano Comparação]],"Verd","Fals") -> Verd | H31: 0 | I31: 0 | J31: 0
B32: =Fluxo_de_Caixa_Janeiro[[#This Row],[Fluxo de Caixa 2026 CTR]] -> 1.1.01. Receita de Cheque Pré | C32: =H32+I32+J32 -> 0 | D32: =IF(C32=0,"0,00%",C32/$C$332) -> 0,00% | E32: 0.0063111634 | F32: =IF(Fluxo_de_Caixa_Janeiro34591171012151619[[#This Row],[% ACUMULADO DEZ/2026]]>=Fluxo_de_Caixa_Janeiro34591171012151619[[#This Row],[% Acum no Ano Comparação]],"Verd","Fals") -> Verd | H32: 0 | I32: 0 | J32: 0
B33: =Fluxo_de_Caixa_Janeiro[[#This Row],[Fluxo de Caixa 2026 CTR]] -> 1.1.01. Recebimento de Carteira (Notinha) | C33: =H33+I33+J33 -> 190040.35 | D33: =IF(C33=0,"0,00%",C33/$C$332) -> 0.099073148 | E33: 0.0001318638 | F33: =IF(Fluxo_de_Caixa_Janeiro34591171012151619[[#This Row],[% ACUMULADO DEZ/2026]]>=Fluxo_de_Caixa_Janeiro34591171012151619[[#This Row],[% Acum no Ano Comparação]],"Verd","Fals") -> Verd | G33: =C361 -> 220.66 | H33: 0 | I33: 158995.12 | J33: 31045.23
B34: =Fluxo_de_Caixa_Janeiro[[#This Row],[Fluxo de Caixa 2026 CTR]] -> 1.1.01. Recebimento de Boletos | C34: =H34+I34+J34 -> 395244.86 | D34: =IF(C34=0,"0,00%",C34/$C$332) -> 0.20605178 | E34: 0.66745712 | F34: =IF(Fluxo_de_Caixa_Janeiro34591171012151619[[#This Row],[% ACUMULADO DEZ/2026]]>=Fluxo_de_Caixa_Janeiro34591171012151619[[#This Row],[% Acum no Ano Comparação]],"Verd","Fals") -> Verd | H34: 46254.07 | I34: 122115.09 | J34: 226875.7
B35: =Fluxo_de_Caixa_Janeiro[[#This Row],[Fluxo de Caixa 2026 CTR]] -> 1.1.01. Recebimento em Depósito e Dep. PIX | C35: =H35+I35+J35 -> 389339.26 | D35: =IF(C35=0,"0,00%",C35/$C$332) -> 0.20297303 | E35: 0.036171198 | F35: =IF(Fluxo_de_Caixa_Janeiro34591171012151619[[#This Row],[% ACUMULADO DEZ/2026]]>=Fluxo_de_Caixa_Janeiro34591171012151619[[#This Row],[% Acum no Ano Comparação]],"Verd","Fals") -> Verd | H35: 1080 | I35: =143749.27 -> 143749.27 | J35: 244509.99
B36: =Fluxo_de_Caixa_Janeiro[[#This Row],[Fluxo de Caixa 2026 CTR]] -> 1.1.02. Recebimento Cheque Devolvido | C36: =H36+I36+J36 -> 0 | D36: =IF(C36=0,"0,00%",C36/$C$332) -> 0,00% | E36: 0.00016817802 | F36: =IF(Fluxo_de_Caixa_Janeiro34591171012151619[[#This Row],[% ACUMULADO DEZ/2026]]>=Fluxo_de_Caixa_Janeiro34591171012151619[[#This Row],[% Acum no Ano Comparação]],"Verd","Fals") -> Verd
B37: =Fluxo_de_Caixa_Janeiro[[#This Row],[Fluxo de Caixa 2026 CTR]] -> 0 | D37: =IF(C37=0,"0,00%",C37/$C$332) -> 0,00% | E37: =#REF! -> #REF! | F37: =IF(Fluxo_de_Caixa_Janeiro34591171012151619[[#This Row],[% ACUMULADO DEZ/2026]]>=Fluxo_de_Caixa_Janeiro34591171012151619[[#This Row],[% Acum no Ano Comparação]],"Verd","Fals") -> #REF!
B38: =Fluxo_de_Caixa_Janeiro[[#This Row],[Fluxo de Caixa 2026 CTR]] -> 0 | D38: =IF(C38=0,"0,00%",C38/$C$332) -> 0,00% | E38: =#REF! -> #REF! | F38: =IF(Fluxo_de_Caixa_Janeiro34591171012151619[[#This Row],[% ACUMULADO DEZ/2026]]>=Fluxo_de_Caixa_Janeiro34591171012151619[[#This Row],[% Acum no Ano Comparação]],"Verd","Fals") -> #REF!
B39: =Fluxo_de_Caixa_Janeiro[[#This Row],[Fluxo de Caixa 2026 CTR]] -> 0 | D39: =IF(C39=0,"0,00%",C39/$C$332) -> 0,00% | E39: =#REF! -> #REF! | F39: =IF(Fluxo_de_Caixa_Janeiro34591171012151619[[#This Row],[% ACUMULADO DEZ/2026]]>=Fluxo_de_Caixa_Janeiro34591171012151619[[#This Row],[% Acum no Ano Comparação]],"Verd","Fals") -> #REF!
B40: =Fluxo_de_Caixa_Janeiro[[#This Row],[Fluxo de Caixa 2026 CTR]] -> 0 | D40: =IF(C40=0,"0,00%",C40/$C$332) -> 0,00% | E40: =#REF! -> #REF! | F40: =IF(Fluxo_de_Caixa_Janeiro34591171012151619[[#This Row],[% ACUMULADO DEZ/2026]]>=Fluxo_de_Caixa_Janeiro34591171012151619[[#This Row],[% Acum no Ano Comparação]],"Verd","Fals") -> #REF!
B41: =Fluxo_de_Caixa_Janeiro[[#This Row],[Fluxo de Caixa 2026 CTR]] -> 0 | D41: =IF(C41=0,"0,00%",C41/$C$332) -> 0,00% | E41: =#REF! -> #REF! | F41: =IF(Fluxo_de_Caixa_Janeiro34591171012151619[[#This Row],[% ACUMULADO DEZ/2026]]>=Fluxo_de_Caixa_Janeiro34591171012151619[[#This Row],[% Acum no Ano Comparação]],"Verd","Fals") -> #REF!
...

Sheet 1 Tri 2026
B1: Fluxo de Caixa 2026 CTR | C1: Janeiro | D1: Fevereiro | E1: Março | F1: Abril | G1: Maio | H1: Junho | I1: Julho | J1: Agosto | K1: Setembro | L1: Outubro | M1: Novembro | N1: Dezembro | O1: Total | P1: % ACUMULADO 1º Trimes 2026 | Q1: % ACUMULADO 1º Trimes 2025 | V1: Total | W1: % ACUMULADO 1º SEMEST 2025
A2: Disponíveis Nas Contas Movimento | B2: =Fluxo_de_Caixa_Janeiro[[#This Row],[Fluxo de Caixa 2026 CTR]] -> Disponíveis Nas Contas Movimento inicial | C2: =Fluxo_de_Caixa_Janeiro[[#This Row],[Janeiro]] -> 67410.42 | D2: =Fluxo_de_Caixa_Janeiro3[[#This Row],[Fevereiro]] -> 31847.63 | E2: =Fluxo_de_Caixa_Janeiro34[[#This Row],[Março]] -> 8957.59 | O2: =Fluxo_de_Caixa_Janeiro31020[[#This Row],[Janeiro]] -> 67410.42 | P2: =SUM(P3:P26) -> 0.8770647 | V2: 192641.1 | W2: 1.0452093
B3: =Fluxo_de_Caixa_Janeiro[[#This Row],[Fluxo de Caixa 2026 CTR]] -> 1.0 - TESOURARIA MATRIZ PALMAS | C3: =Fluxo_de_Caixa_Janeiro[[#This Row],[Janeiro]] -> 148.53 | D3: =Fluxo_de_Caixa_Janeiro3[[#This Row],[Fevereiro]] -> 40.53 | E3: =Fluxo_de_Caixa_Janeiro34[[#This Row],[Março]] -> 337.58 | O3: =Fluxo_de_Caixa_Janeiro31020[[#This Row],[Janeiro]] -> 148.53 | P3: =IF(O3=0,"0,00%",O3/$O$2) -> 0.0022033686 | V3: 375.53 | W3: 0.0019493763
B4: =Fluxo_de_Caixa_Janeiro[[#This Row],[Fluxo de Caixa 2026 CTR]] -> 1.1 - BANCO DO BRASIL C.C.60409-7 MATRIZ | C4: =Fluxo_de_Caixa_Janeiro[[#This Row],[Janeiro]] -> 15268.12 | D4: =Fluxo_de_Caixa_Janeiro3[[#This Row],[Fevereiro]] -> 108.85 | E4: =Fluxo_de_Caixa_Janeiro34[[#This Row],[Março]] -> 55.77 | I4: =#REF! -> #REF! | J4: =#REF! -> #REF! | K4: =#REF! -> #REF! | L4: =#REF! -> #REF! | M4: =#REF! -> #REF! | N4: =#REF! -> #REF! | O4: =Fluxo_de_Caixa_Janeiro31020[[#This Row],[Janeiro]] -> 15268.12 | P4: =IF(O4=0,"0,00%",O4/$O$2) -> 0.22649495 | V4: 0 | W4: 0,00%
B5: =Fluxo_de_Caixa_Janeiro[[#This Row],[Fluxo de Caixa 2026 CTR]] -> 0 | C5: =Fluxo_de_Caixa_Janeiro[[#This Row],[Janeiro]] -> 0 | D5: =Fluxo_de_Caixa_Janeiro3[[#This Row],[Fevereiro]] -> 0 | E5: =Fluxo_de_Caixa_Janeiro34[[#This Row],[Março]] -> 0 | I5: =#REF! -> #REF! | J5: =#REF! -> #REF! | K5: =#REF! -> #REF! | L5: =#REF! -> #REF! | M5: =#REF! -> #REF! | N5: =#REF! -> #REF! | O5: =Fluxo_de_Caixa_Janeiro31020[[#This Row],[Janeiro]] -> 0 | P5: =IF(O5=0,"0,00%",O5/$O$2) -> 0,00% | V5: 0 | W5: 0,00%
B6: =Fluxo_de_Caixa_Janeiro[[#This Row],[Fluxo de Caixa 2026 CTR]] -> 1.2-BRADESCO 15232-3 MATRIZ | C6: =Fluxo_de_Caixa_Janeiro[[#This Row],[Janeiro]] -> 8.62 | D6: =Fluxo_de_Caixa_Janeiro3[[#This Row],[Fevereiro]] -> 3332.91 | E6: =Fluxo_de_Caixa_Janeiro34[[#This Row],[Março]] -> 25.97 | I6: =#REF! -> #REF! | J6: =#REF! -> #REF! | K6: =#REF! -> #REF! | L6: =#REF! -> #REF! | M6: =#REF! -> #REF! | N6: =#REF! -> #REF! | O6: =Fluxo_de_Caixa_Janeiro31020[[#This Row],[Janeiro]] -> 8.62 | P6: =IF(O6=0,"0,00%",O6/$O$2) -> 0.00012787341 | V6: 134596.86 | W6: 0.69869234
B7: =Fluxo_de_Caixa_Janeiro[[#This Row],[Fluxo de Caixa 2026 CTR]] -> 0 | C7: =Fluxo_de_Caixa_Janeiro[[#This Row],[Janeiro]] -> 0 | D7: =Fluxo_de_Caixa_Janeiro3[[#This Row],[Fevereiro]] -> 0 | E7: =Fluxo_de_Caixa_Janeiro34[[#This Row],[Março]] -> 0 | I7: =#REF! -> #REF! | J7: =#REF! -> #REF! | K7: =#REF! -> #REF! | L7: =#REF! -> #REF! | M7: =#REF! -> #REF! | N7: =#REF! -> #REF! | O7: =Fluxo_de_Caixa_Janeiro31020[[#This Row],[Janeiro]] -> 0 | P7: =IF(O7=0,"0,00%",O7/$O$2) -> 0,00% | V7: 0 | W7: 0,00%
B8: =Fluxo_de_Caixa_Janeiro[[#This Row],[Fluxo de Caixa 2026 CTR]] -> 1.3 - BANCO STONE MATRIZ C.C 40256726-7 | C8: =Fluxo_de_Caixa_Janeiro[[#This Row],[Janeiro]] -> 0 | D8: =Fluxo_de_Caixa_Janeiro3[[#This Row],[Fevereiro]] -> 2671 | E8: =Fluxo_de_Caixa_Janeiro34[[#This Row],[Março]] -> 0 | I8: =#REF! -> #REF! | J8: =#REF! -> #REF! | K8: =#REF! -> #REF! | L8: =#REF! -> #REF! | M8: =#REF! -> #REF! | N8: =#REF! -> #REF! | O8: =Fluxo_de_Caixa_Janeiro31020[[#This Row],[Janeiro]] -> 0 | P8: =IF(O8=0,"0,00%",O8/$O$2) -> 0,00% | V8: 26517.91 | W8: 0.13765448
B9: =Fluxo_de_Caixa_Janeiro[[#This Row],[Fluxo de Caixa 2026 CTR]] -> 1.4 - BANCO DA AMAZONIA 071730-7 MATRIZ | C9: =Fluxo_de_Caixa_Janeiro[[#This Row],[Janeiro]] -> 124.56 | D9: =Fluxo_de_Caixa_Janeiro3[[#This Row],[Fevereiro]] -> 281.78 | E9: =Fluxo_de_Caixa_Janeiro34[[#This Row],[Março]] -> 1900.51 | I9: =#REF! -> #REF! | J9: =#REF! -> #REF! | K9: =#REF! -> #REF! | L9: =#REF! -> #REF! | M9: =#REF! -> #REF! | N9: =#REF! -> #REF! | O9: =Fluxo_de_Caixa_Janeiro31020[[#This Row],[Janeiro]] -> 124.56 | P9: =IF(O9=0,"0,00%",O9/$O$2) -> 0.0018477856 | V9: 0 | W9: 0,00%
B10: =Fluxo_de_Caixa_Janeiro[[#This Row],[Fluxo de Caixa 2026 CTR]] -> 1.4.1.INVESTIMENTO CDBORE RCP TXFL | C10: =Fluxo_de_Caixa_Janeiro[[#This Row],[Janeiro]] -> 0 | D10: =Fluxo_de_Caixa_Janeiro3[[#This Row],[Fevereiro]] -> 0 | E10: =Fluxo_de_Caixa_Janeiro34[[#This Row],[Março]] -> 0 | I10: =#REF! -> #REF! | J10: =#REF! -> #REF! | K10: =#REF! -> #REF! | L10: =#REF! -> #REF! | M10: =#REF! -> #REF! | N10: =#REF! -> #REF! | O10: =Fluxo_de_Caixa_Janeiro31020[[#This Row],[Janeiro]] -> 0 | P10: =IF(O10=0,"0,00%",O10/$O$2) -> 0,00% | V10: 5717.64 | W10: 0.029680271
B11: =Fluxo_de_Caixa_Janeiro[[#This Row],[Fluxo de Caixa 2026 CTR]] -> 1.5 - ITAU C.C.98671-6 MATRIZ | C11: =Fluxo_de_Caixa_Janeiro[[#This Row],[Janeiro]] -> 40443.69 | D11: =Fluxo_de_Caixa_Janeiro3[[#This Row],[Fevereiro]] -> 18153.73 | E11: =Fluxo_de_Caixa_Janeiro34[[#This Row],[Março]] -> 33831.3 | I11: =#REF! -> #REF! | J11: =#REF! -> #REF! | K11: =#REF! -> #REF! | L11: =#REF! -> #REF! | M11: =#REF! -> #REF! | N11: =#REF! -> #REF! | O11: =Fluxo_de_Caixa_Janeiro31020[[#This Row],[Janeiro]] -> 40443.69 | P11: =IF(O11=0,"0,00%",O11/$O$2) -> 0.59996199 | V11: 0 | W11: 0,00%
B12: =Fluxo_de_Caixa_Janeiro[[#This Row],[Fluxo de Caixa 2026 CTR]] -> 1.5.03. ITAU C.C 83290-2 GARANTIDA | C12: =Fluxo_de_Caixa_Janeiro[[#This Row],[Janeiro]] -> 902.73 | D12: =Fluxo_de_Caixa_Janeiro3[[#This Row],[Fevereiro]] -> 1286.28 | E12: =Fluxo_de_Caixa_Janeiro34[[#This Row],[Março]] -> 5399.76 | I12: =#REF! -> #REF! | J12: =#REF! -> #REF! | K12: =#REF! -> #REF! | L12: =#REF! -> #REF! | M12: =#REF! -> #REF! | N12: =#REF! -> #REF! | O12: =Fluxo_de_Caixa_Janeiro31020[[#This Row],[Janeiro]] -> 902.73 | P12: =IF(O12=0,"0,00%",O12/$O$2) -> 0.01339155 | V12: 0 | W12: 0,00%
B13: =Fluxo_de_Caixa_Janeiro[[#This Row],[Fluxo de Caixa 2026 CTR]] -> 1.9 - CONTA PERDA/ROUBO/BONIFICAÇÃO E DOAÇÃO | C13: =Fluxo_de_Caixa_Janeiro[[#This Row],[Janeiro]] -> 0 | D13: =Fluxo_de_Caixa_Janeiro3[[#This Row],[Fevereiro]] -> 0 | E13: =Fluxo_de_Caixa_Janeiro34[[#This Row],[Março]] -> -20953.13 | O13: =Fluxo_de_Caixa_Janeiro31020[[#This Row],[Janeiro]] -> 0 | P13: =IF(O13=0,"0,00%",O13/$O$2) -> 0,00% | V13: -2553.05 | W13: -0.013252883
B14: =Fluxo_de_Caixa_Janeiro[[#This Row],[Fluxo de Caixa 2026 CTR]] -> 0 | C14: =Fluxo_de_Caixa_Janeiro[[#This Row],[Janeiro]] -> 0 | D14: =Fluxo_de_Caixa_Janeiro3[[#This Row],[Fevereiro]] -> 0 | E14: =Fluxo_de_Caixa_Janeiro34[[#This Row],[Março]] -> 0 | O14: =Fluxo_de_Caixa_Janeiro31020[[#This Row],[Janeiro]] -> 0 | P14: =IF(O14=0,"0,00%",O14/$O$2) -> 0,00% | V14: 0 | W14: 0
B15: =Fluxo_de_Caixa_Janeiro[[#This Row],[Fluxo de Caixa 2026 CTR]] -> 2.1 - BANCO DO BRASIL C.C.60638-3 FILIAL PALMAS | C15: =Fluxo_de_Caixa_Janeiro[[#This Row],[Janeiro]] -> 1415.61 | D15: =Fluxo_de_Caixa_Janeiro3[[#This Row],[Fevereiro]] -> 1829.48 | E15: =Fluxo_de_Caixa_Janeiro34[[#This Row],[Março]] -> 65.56 | O15: =Fluxo_de_Caixa_Janeiro31020[[#This Row],[Janeiro]] -> 1415.61 | P15: =IF(O15=0,"0,00%",O15/$O$2) -> 0.020999869 | V15: 158.24 | W15: 0.00082142388
B16: =Fluxo_de_Caixa_Janeiro[[#This Row],[Fluxo de Caixa 2026 CTR]] -> 0 | C16: =Fluxo_de_Caixa_Janeiro[[#This Row],[Janeiro]] -> 0 | D16: =Fluxo_de_Caixa_Janeiro3[[#This Row],[Fevereiro]] -> 0 | E16: =Fluxo_de_Caixa_Janeiro34[[#This Row],[Março]] -> 0 | O16: =Fluxo_de_Caixa_Janeiro31020[[#This Row],[Janeiro]] -> 0 | P16: =IF(O16=0,"0,00%",O16/$O$2) -> 0,00% | V16: -1.79 | W16: -9.2918905e-06
B17: =Fluxo_de_Caixa_Janeiro[[#This Row],[Fluxo de Caixa 2026 CTR]] -> 0 | C17: =Fluxo_de_Caixa_Janeiro[[#This Row],[Janeiro]] -> 0 | D17: =Fluxo_de_Caixa_Janeiro3[[#This Row],[Fevereiro]] -> 0 | E17: =Fluxo_de_Caixa_Janeiro34[[#This Row],[Março]] -> 0 | O17: =Fluxo_de_Caixa_Janeiro31020[[#This Row],[Janeiro]] -> 0 | P17: =IF(O17=0,"0,00%",O17/$O$2) -> 0,00% | V17: 0 | W17: 0
B18: =Fluxo_de_Caixa_Janeiro[[#This Row],[Fluxo de Caixa 2026 CTR]] -> 2.4 - ITAU C.C.98669-0 FILIAL PALMAS | C18: =Fluxo_de_Caixa_Janeiro[[#This Row],[Janeiro]] -> 536.72 | D18: =Fluxo_de_Caixa_Janeiro3[[#This Row],[Fevereiro]] -> 536.72 | E18: =Fluxo_de_Caixa_Janeiro34[[#This Row],[Março]] -> 37.73 | O18: =Fluxo_de_Caixa_Janeiro31020[[#This Row],[Janeiro]] -> 536.72 | P18: =IF(O18=0,"0,00%",O18/$O$2) -> 0.0079619738 | V18: 26883.69 | W18: 0.13955324
B19: =Fluxo_de_Caixa_Janeiro[[#This Row],[Fluxo de Caixa 2026 CTR]] -> 2.9 - CONTA PERDA/ROUBO E BONIFICAÇÃO FILIAL | C19: =Fluxo_de_Caixa_Janeiro[[#This Row],[Janeiro]] -> 0 | D19: =Fluxo_de_Caixa_Janeiro3[[#This Row],[Fevereiro]] -> -219.15 | E19: =Fluxo_de_Caixa_Janeiro34[[#This Row],[Março]] -> -8598.58 | O19: =SUM(Fluxo_de_Caixa_Janeiro31020[[#This Row],[Janeiro]:[Dezembro]]) -> -8817.73 | P19: =IF(O19=0,"0,00%",O19/$O$2) -> -0.13080663 | V19: 2838.21 | W19: 0.014733149
B20: =Fluxo_de_Caixa_Janeiro[[#This Row],[Fluxo de Caixa 2026 CTR]] -> 4.0 - TESOURARIA FILIAL PORTO | C20: =Fluxo_de_Caixa_Janeiro[[#This Row],[Janeiro]] -> 1409.97 | D20: =Fluxo_de_Caixa_Janeiro3[[#This Row],[Fevereiro]] -> 385.51 | E20: =Fluxo_de_Caixa_Janeiro34[[#This Row],[Março]] -> 1327.43 | O20: =SUM(Fluxo_de_Caixa_Janeiro31020[[#This Row],[Janeiro]:[Dezembro]]) -> 3122.91 | P20: =IF(O20=0,"0,00%",O20/$O$2) -> 0.046326814 | V20: 0 | W20: 0,00%
B21: =Fluxo_de_Caixa_Janeiro[[#This Row],[Fluxo de Caixa 2026 CTR]] -> 4.1 - BANCO DO BRASIL C.C.61105-0 FILIAL PORTO | C21: =Fluxo_de_Caixa_Janeiro[[#This Row],[Janeiro]] -> 57.34 | D21: =Fluxo_de_Caixa_Janeiro3[[#This Row],[Fevereiro]] -> 16.83 | E21: =Fluxo_de_Caixa_Janeiro34[[#This Row],[Março]] -> 111.93 | O21: =SUM(Fluxo_de_Caixa_Janeiro31020[[#This Row],[Janeiro]:[Dezembro]]) -> 186.1 | P21: =IF(O21=0,"0,00%",O21/$O$2) -> 0.0027607008 | V21: 0 | W21: 0,00%
B22: =Fluxo_de_Caixa_Janeiro[[#This Row],[Fluxo de Caixa 2026 CTR]] -> 0 | C22: =Fluxo_de_Caixa_Janeiro[[#This Row],[Janeiro]] -> 0 | D22: =Fluxo_de_Caixa_Janeiro3[[#This Row],[Fevereiro]] -> 0 | E22: =Fluxo_de_Caixa_Janeiro34[[#This Row],[Março]] -> 0 | O22: =SUM(Fluxo_de_Caixa_Janeiro31020[[#This Row],[Janeiro]:[Dezembro]]) -> 0 | P22: =IF(O22=0,"0,00%",O22/$O$2) -> 0,00% | V22: 0 | W22: 0,00%
B23: =Fluxo_de_Caixa_Janeiro[[#This Row],[Fluxo de Caixa 2026 CTR]] -> 4.4 - MERCADO PAGO PIX FILIAL PORTO | C23: =Fluxo_de_Caixa_Janeiro[[#This Row],[Janeiro]] -> 5412.19 | D23: =Fluxo_de_Caixa_Janeiro3[[#This Row],[Fevereiro]] -> 2060.42 | E23: =Fluxo_de_Caixa_Janeiro34[[#This Row],[Março]] -> 22539.57 | O23: =SUM(Fluxo_de_Caixa_Janeiro31020[[#This Row],[Janeiro]:[Dezembro]]) -> 30012.18 | P23: =IF(O23=0,"0,00%",O23/$O$2) -> 0.44521574 | V23: 5332.04 | W23: 0.027678621
B24: =Fluxo_de_Caixa_Janeiro[[#This Row],[Fluxo de Caixa 2026 CTR]] -> 4.9 - CONTA PERDA/ROUBO E BONIFICAÇÃO FILIAL | C24: =Fluxo_de_Caixa_Janeiro[[#This Row],[Janeiro]] -> 0 | D24: =Fluxo_de_Caixa_Janeiro3[[#This Row],[Fevereiro]] -> 0 | E24: =Fluxo_de_Caixa_Janeiro34[[#This Row],[Março]] -> -29071.86 | O24: =SUM(Fluxo_de_Caixa_Janeiro31020[[#This Row],[Janeiro]:[Dezembro]]) -> -29071.86 | P24: =IF(O24=0,"0,00%",O24/$O$2) -> -0.43126656 | V24: 770.18 | W24: 0.0039980046
B25: =Fluxo_de_Caixa_Janeiro[[#This Row],[Fluxo de Caixa 2026 CTR]] -> 91.CARTÃO ENDERED 5099+4596+6933+8072 - ESCRITORIO | C25: =Fluxo_de_Caixa_Janeiro[[#This Row],[Janeiro]] -> 1682.34 | D25: =Fluxo_de_Caixa_Janeiro3[[#This Row],[Fevereiro]] -> 1362.74 | E25: =Fluxo_de_Caixa_Janeiro34[[#This Row],[Março]] -> 1948.05 | O25: =SUM(Fluxo_de_Caixa_Janeiro31020[[#This Row],[Janeiro]:[Dezembro]]) -> 4993.13 | P25: =IF(O25=0,"0,00%",O25/$O$2) -> 0.074070596 | V25: 714.8 | W25: 0.003710527
B26: =Fluxo_de_Caixa_Janeiro[[#This Row],[Fluxo de Caixa 2026 CTR]] -> 0 | C26: =Fluxo_de_Caixa_Janeiro[[#This Row],[Janeiro]] -> 0 | D26: =Fluxo_de_Caixa_Janeiro3[[#This Row],[Fevereiro]] -> -150.01 | E26: =Fluxo_de_Caixa_Janeiro34[[#This Row],[Março]] -> 0 | O26: =SUM(Fluxo_de_Caixa_Janeiro31020[[#This Row],[Janeiro]:[Dezembro]]) -> -150.01 | P26: =IF(O26=0,"0,00%",O26/$O$2) -> -0.0022253236 | V26: 1.7462298e-10 | W26: 9.0646795e-16
B27: =Fluxo_de_Caixa_Janeiro[[#This Row],[Fluxo de Caixa 2026 CTR]] -> Total Receitas Operacionais / Vendas | C27: =Fluxo_de_Caixa_Janeiro[[#This Row],[Janeiro]] -> 749632.93 | D27: =Fluxo_de_Caixa_Janeiro3[[#This Row],[Fevereiro]] -> 1038589.1 | E27: =Fluxo_de_Caixa_Janeiro34[[#This Row],[Março]] -> 1087750 | O27: =SUM(Fluxo_de_Caixa_Janeiro31020[[#This Row],[Janeiro]:[Dezembro]]) -> 2875972 | P27: =IFERROR(O27/O332,"0,00%") -> 0.7756588 | Q27: 0.98042161 | R27: =IF(Fluxo_de_Caixa_Janeiro31020[[#This Row],[% ACUMULADO 1º Trimes 2026]]>=Fluxo_de_Caixa_Janeiro31020[[#This Row],[% ACUMULADO 1º Trimes 2025]],"VERDADEIRO","FALSO") -> FALSO | T27: =V27-Fluxo_de_Caixa_Janeiro31020[[#This Row],[Total]] -> -185520.07 | V27: 2690451.9 | W27: 0.98042161
A28: 1.1. Receita com Vendas | B28: =Fluxo_de_Caixa_Janeiro[[#This Row],[Fluxo de Caixa 2026 CTR]] -> 1.1. Receita com Vendas | C28: =Fluxo_de_Caixa_Janeiro[[#This Row],[Janeiro]] -> 749632.93 | D28: =Fluxo_de_Caixa_Janeiro3[[#This Row],[Fevereiro]] -> 1038589.1 | E28: =Fluxo_de_Caixa_Janeiro34[[#This Row],[Março]] -> 1087750 | O28: =SUM(Fluxo_de_Caixa_Janeiro31020[[#This Row],[Janeiro]:[Dezembro]]) -> 2875972 | P28: =SUM(P29:P47) -> 0.7756588 | Q28: 0.98042161 | R28: =IF(Fluxo_de_Caixa_Janeiro31020[[#This Row],[% ACUMULADO 1º Trimes 2026]]>=Fluxo_de_Caixa_Janeiro31020[[#This Row],[% ACUMULADO 1º Trimes 2025]],"VERDADEIRO","FALSO") -> FALSO | V28: 2690451.9 | W28: 0.98042161
B29: =Fluxo_de_Caixa_Janeiro[[#This Row],[Fluxo de Caixa 2026 CTR]] -> 1.1.01. Receita em Dinheiro | C29: =Fluxo_de_Caixa_Janeiro[[#This Row],[Janeiro]] -> 2199.78 | D29: =Fluxo_de_Caixa_Janeiro3[[#This Row],[Fevereiro]] -> 4660.37 | E29: =Fluxo_de_Caixa_Janeiro34[[#This Row],[Março]] -> 2754.35 | O29: =SUM(Fluxo_de_Caixa_Janeiro31020[[#This Row],[Janeiro]:[Dezembro]]) -> 9614.5 | P29: =IF(O29=0,"0,00%",O29/$O$332) -> 0.0025930612 | Q29: 0.0080947211 | R29: =IF(Fluxo_de_Caixa_Janeiro31020[[#This Row],[% ACUMULADO 1º Trimes 2026]]>=Fluxo_de_Caixa_Janeiro31020[[#This Row],[% ACUMULADO 1º Trimes 2025]],"VERDADEIRO","FALSO") -> FALSO | V29: 22213.36 | W29: 0.0080947211
B30: =Fluxo_de_Caixa_Janeiro[[#This Row],[Fluxo de Caixa 2026 CTR]] -> 1.1.01. Receita em Cartão (Crédito e Débito) | C30: =Fluxo_de_Caixa_Janeiro[[#This Row],[Janeiro]] -> 328505.72 | D30: =Fluxo_de_Caixa_Janeiro3[[#This Row],[Fevereiro]] -> 221053.51 | E30: =Fluxo_de_Caixa_Janeiro34[[#This Row],[Março]] -> 110371.17 | O30: =SUM(Fluxo_de_Caixa_Janeiro31020[[#This Row],[Janeiro]:[Dezembro]]) -> 659930.4 | P30: =IF(O30=0,"0,00%",O30/$O$332) -> 0.17798533 | Q30: 0.060278818 | R30: =IF(Fluxo_de_Caixa_Janeiro31020[[#This Row],[% ACUMULADO 1º Trimes 2026]]>=Fluxo_de_Caixa_Janeiro31020[[#This Row],[% ACUMULADO 1º Trimes 2025]],"VERDADEIRO","FALSO") -> VERDADEIRO | V30: 165415.84 | W30: 0.060278818
B31: =Fluxo_de_Caixa_Janeiro[[#This Row],[Fluxo de Caixa 2026 CTR]] -> 1.1.01. Receita de Cheque A Vista | C31: =Fluxo_de_Caixa_Janeiro[[#This Row],[Janeiro]] -> 15000 | D31: =Fluxo_de_Caixa_Janeiro3[[#This Row],[Fevereiro]] -> 26907.75 | E31: =Fluxo_de_Caixa_Janeiro34[[#This Row],[Março]] -> 0 | O31: =SUM(Fluxo_de_Caixa_Janeiro31020[[#This Row],[Janeiro]:[Dezembro]]) -> 41907.75 | P31: =IF(O31=0,"0,00%",O31/$O$332) -> 0.011302653 | Q31: 0,00% | R31: =IF(Fluxo_de_Caixa_Janeiro31020[[#This Row],[% ACUMULADO 1º Trimes 2026]]>=Fluxo_de_Caixa_Janeiro31020[[#This Row],[% ACUMULADO 1º Trimes 2025]],"VERDADEIRO","FALSO") -> FALSO | V31: 0 | W31: 0,00%
B32: =Fluxo_de_Caixa_Janeiro[[#This Row],[Fluxo de Caixa 2026 CTR]] -> 1.1.01. Receita de Cheque Pré | C32: =Fluxo_de_Caixa_Janeiro[[#This Row],[Janeiro]] -> 0 | D32: =Fluxo_de_Caixa_Janeiro3[[#This Row],[Fevereiro]] -> 0 | E32: =Fluxo_de_Caixa_Janeiro34[[#This Row],[Março]] -> 0 | O32: =SUM(Fluxo_de_Caixa_Janeiro31020[[#This Row],[Janeiro]:[Dezembro]]) -> 0 | P32: =IF(O32=0,"0,00%",O32/$O$332) -> 0,00% | Q32: 0,00% | R32: =IF(Fluxo_de_Caixa_Janeiro31020[[#This Row],[% ACUMULADO 1º Trimes 2026]]>=Fluxo_de_Caixa_Janeiro31020[[#This Row],[% ACUMULADO 1º Trimes 2025]],"VERDADEIRO","FALSO") -> VERDADEIRO | V32: 0 | W32: 0,00%
B33: =Fluxo_de_Caixa_Janeiro[[#This Row],[Fluxo de Caixa 2026 CTR]] -> 1.1.01. Recebimento de Carteira (Notinha) | C33: =Fluxo_de_Caixa_Janeiro[[#This Row],[Janeiro]] -> 0 | D33: =Fluxo_de_Caixa_Janeiro3[[#This Row],[Fevereiro]] -> 0 | E33: =Fluxo_de_Caixa_Janeiro34[[#This Row],[Março]] -> 190040.35 | O33: =SUM(Fluxo_de_Caixa_Janeiro31020[[#This Row],[Janeiro]:[Dezembro]]) -> 190040.35 | P33: =IF(O33=0,"0,00%",O33/$O$332) -> 0.051254487 | Q33: 0.28301373 | R33: =IF(Fluxo_de_Caixa_Janeiro31020[[#This Row],[% ACUMULADO 1º Trimes 2026]]>=Fluxo_de_Caixa_Janeiro31020[[#This Row],[% ACUMULADO 1º Trimes 2025]],"VERDADEIRO","FALSO") -> FALSO | V33: 776640.22 | W33: 0.28301373
B34: =Fluxo_de_Caixa_Janeiro[[#This Row],[Fluxo de Caixa 2026 CTR]] -> 1.1.01. Recebimento de Boletos | C34: =Fluxo_de_Caixa_Janeiro[[#This Row],[Janeiro]] -> 144411.43 | D34: =Fluxo_de_Caixa_Janeiro3[[#This Row],[Fevereiro]] -> 317162.15 | E34: =Fluxo_de_Caixa_Janeiro34[[#This Row],[Março]] -> 395244.86 | O34: =SUM(Fluxo_de_Caixa_Janeiro31020[[#This Row],[Janeiro]:[Dezembro]]) -> 856818.44 | P34: =IF(O34=0,"0,00%",O34/$O$332) -> 0.23108666 | Q34: 0.40013718 | R34: =IF(Fluxo_de_Caixa_Janeiro31020[[#This Row],[% ACUMULADO 1º Trimes 2026]]>=Fluxo_de_Caixa_Janeiro31020[[#This Row],[% ACUMULADO 1º Trimes 2025]],"VERDADEIRO","FALSO") -> FALSO | V34: 1098047.9 | W34: 0.40013718
B35: =Fluxo_de_Caixa_Janeiro[[#This Row],[Fluxo de Caixa 2026 CTR]] -> 1.1.01. Recebimento em Depósito e Dep. PIX | C35: =Fluxo_de_Caixa_Janeiro[[#This Row],[Janeiro]] -> 259516 | D35: =Fluxo_de_Caixa_Janeiro3[[#This Row],[Fevereiro]] -> 468805.31 | E35: =Fluxo_de_Caixa_Janeiro34[[#This Row],[Março]] -> 389339.26 | O35: =SUM(Fluxo_de_Caixa_Janeiro31020[[#This Row],[Janeiro]:[Dezembro]]) -> 1117660.6 | P35: =IF(O35=0,"0,00%",O35/$O$332) -> 0.30143661 | Q35: 0.22889715 | R35: =IF(Fluxo_de_Caixa_Janeiro31020[[#This Row],[% ACUMULADO 1º Trimes 2026]]>=Fluxo_de_Caixa_Janeiro31020[[#This Row],[% ACUMULADO 1º Trimes 2025]],"VERDADEIRO","FALSO") -> VERDADEIRO | V35: 628134.64 | W35: 0.22889715
B36: =Fluxo_de_Caixa_Janeiro[[#This Row],[Fluxo de Caixa 2026 CTR]] -> 1.1.02. Recebimento Cheque Devolvido | C36: =Fluxo_de_Caixa_Janeiro[[#This Row],[Janeiro]] -> 0 | D36: =Fluxo_de_Caixa_Janeiro3[[#This Row],[Fevereiro]] -> 0 | E36: =Fluxo_de_Caixa_Janeiro34[[#This Row],[Março]] -> 0 | O36: =SUM(Fluxo_de_Caixa_Janeiro31020[[#This Row],[Janeiro]:[Dezembro]]) -> 0 | P36: =IF(O36=0,"0,00%",O36/$O$332) -> 0,00% | Q36: 0,00% | R36: =IF(Fluxo_de_Caixa_Janeiro31020[[#This Row],[% ACUMULADO 1º Trimes 2026]]>=Fluxo_de_Caixa_Janeiro31020[[#This Row],[% ACUMULADO 1º Trimes 2025]],"VERDADEIRO","FALSO") -> VERDADEIRO | V36: 0 | W36: 0,00%
B37: =Fluxo_de_Caixa_Janeiro[[#This Row],[Fluxo de Caixa 2026 CTR]] -> 0 | C37: =Fluxo_de_Caixa_Janeiro[[#This Row],[Janeiro]] -> 0 | D37: =Fluxo_de_Caixa_Janeiro3[[#This Row],[Fevereiro]] -> 0 | E37: =Fluxo_de_Caixa_Janeiro34[[#This Row],[Março]] -> 0 | O37: =SUM(Fluxo_de_Caixa_Janeiro31020[[#This Row],[Janeiro]:[Dezembro]]) -> 0 | P37: =IF(O37=0,"0,00%",O37/$O$332) -> 0,00% | Q37: 0,00% | R37: =IF(Fluxo_de_Caixa_Janeiro31020[[#This Row],[% ACUMULADO 1º Trimes 2026]]>=Fluxo_de_Caixa_Janeiro31020[[#This Row],[% ACUMULADO 1º Trimes 2025]],"VERDADEIRO","FALSO") -> VERDADEIRO | V37: 0 | W37: 0,00%
B38: =Fluxo_de_Caixa_Janeiro[[#This Row],[Fluxo de Caixa 2026 CTR]] -> 0 | C38: =Fluxo_de_Caixa_Janeiro[[#This Row],[Janeiro]] -> 0 | D38: =Fluxo_de_Caixa_Janeiro3[[#This Row],[Fevereiro]] -> 0 | E38: =Fluxo_de_Caixa_Janeiro34[[#This Row],[Março]] -> 0 | O38: =SUM(Fluxo_de_Caixa_Janeiro31020[[#This Row],[Janeiro]:[Dezembro]]) -> 0 | P38: =IF(O38=0,"0,00%",O38/$O$332) -> 0,00% | Q38: 0,00% | R38: =IF(Fluxo_de_Caixa_Janeiro31020[[#This Row],[% ACUMULADO 1º Trimes 2026]]>=Fluxo_de_Caixa_Janeiro31020[[#This Row],[% ACUMULADO 1º Trimes 2025]],"VERDADEIRO","FALSO") -> VERDADEIRO | V38: 0 | W38: 0,00%
B39: =Fluxo_de_Caixa_Janeiro[[#This Row],[Fluxo de Caixa 2026 CTR]] -> 0 | C39: =Fluxo_de_Caixa_Janeiro[[#This Row],[Janeiro]] -> 0 | D39: =Fluxo_de_Caixa_Janeiro3[[#This Row],[Fevereiro]] -> 0 | E39: =Fluxo_de_Caixa_Janeiro34[[#This Row],[Março]] -> 0 | O39: =SUM(Fluxo_de_Caixa_Janeiro31020[[#This Row],[Janeiro]:[Dezembro]]) -> 0 | P39: =IF(O39=0,"0,00%",O39/$O$332) -> 0,00% | Q39: 0,00% | R39: =IF(Fluxo_de_Caixa_Janeiro31020[[#This Row],[% ACUMULADO 1º Trimes 2026]]>=Fluxo_de_Caixa_Janeiro31020[[#This Row],[% ACUMULADO 1º Trimes 2025]],"VERDADEIRO","FALSO") -> VERDADEIRO | V39: 0 | W39: 0,00%
B40: =Fluxo_de_Caixa_Janeiro[[#This Row],[Fluxo de Caixa 2026 CTR]] -> 0 | C40: =Fluxo_de_Caixa_Janeiro[[#This Row],[Janeiro]] -> 0 | D40: =Fluxo_de_Caixa_Janeiro3[[#This Row],[Fevereiro]] -> 0 | E40: =Fluxo_de_Caixa_Janeiro34[[#This Row],[Março]] -> 0 | O40: =SUM(Fluxo_de_Caixa_Janeiro31020[[#This Row],[Janeiro]:[Dezembro]]) -> 0 | P40: =IF(O40=0,"0,00%",O40/$O$332) -> 0,00% | Q40: 0,00% | R40: =IF(Fluxo_de_Caixa_Janeiro31020[[#This Row],[% ACUMULADO 1º Trimes 2026]]>=Fluxo_de_Caixa_Janeiro31020[[#This Row],[% ACUMULADO 1º Trimes 2025]],"VERDADEIRO","FALSO") -> VERDADEIRO | V40: 0 | W40: 0,00%
...

Sheet ABRIL
B1: Fluxo de Caixa 2026 CTR | C1: ABRIL | D1: % ACUMULADO ABR/2026 | E1: % Acum no Ano Comparação | H1: Matriz | I1: Filia Porto | J1: Filia Palmas
A2: Disponíveis Nas Contas Movimento | B2: =Fluxo_de_Caixa_Janeiro[[#This Row],[Fluxo de Caixa 2026 CTR]] -> Disponíveis Nas Contas Movimento inicial | C2: =SUBTOTAL(109,C3:C26) -> 437595.58 | D2: =SUM(D3:D26) -> 1.0005043
B3: =Fluxo_de_Caixa_Janeiro[[#This Row],[Fluxo de Caixa 2026 CTR]] -> 1.0 - TESOURARIA MATRIZ PALMAS | C3: =MARÇO!C337 -> 850.58 | D3: =IF(C3=0,"0,00%",C3/$C$2) -> 0.0019437582 | G3: 1
B4: =Fluxo_de_Caixa_Janeiro[[#This Row],[Fluxo de Caixa 2026 CTR]] -> 1.1 - BANCO DO BRASIL C.C.60409-7 MATRIZ | C4: =MARÇO!C338 -> 36651.07 | D4: =IF(C4=0,"0,00%",C4/$C$2) -> 0.083755576 | G4: 2
B5: =Fluxo_de_Caixa_Janeiro[[#This Row],[Fluxo de Caixa 2026 CTR]] -> 0 | C5: =MARÇO!C339 -> 0 | D5: =IF(C5=0,"0,00%",C5/$C$2) -> 0,00% | G5: 3
B6: =Fluxo_de_Caixa_Janeiro[[#This Row],[Fluxo de Caixa 2026 CTR]] -> 1.2-BRADESCO 15232-3 MATRIZ | C6: =MARÇO!C340 -> 6785.01 | D6: =IF(C6=0,"0,00%",C6/$C$2) -> 0.015505207 | G6: 4
B7: =Fluxo_de_Caixa_Janeiro[[#This Row],[Fluxo de Caixa 2026 CTR]] -> 0 | C7: =MARÇO!C341 -> 0 | D7: =IF(C7=0,"0,00%",C7/$C$2) -> 0,00% | G7: 5
B8: =Fluxo_de_Caixa_Janeiro[[#This Row],[Fluxo de Caixa 2026 CTR]] -> 1.3 - BANCO STONE MATRIZ C.C 40256726-7 | C8: =MARÇO!C342 -> 0 | D8: =IF(C8=0,"0,00%",C8/$C$2) -> 0,00% | G8: 6
B9: =Fluxo_de_Caixa_Janeiro[[#This Row],[Fluxo de Caixa 2026 CTR]] -> 1.4 - BANCO DA AMAZONIA 071730-7 MATRIZ | C9: =MARÇO!C343 -> 304243.92 | D9: =IF(C9=0,"0,00%",C9/$C$2) -> 0.69526278 | G9: 7
B10: =Fluxo_de_Caixa_Janeiro[[#This Row],[Fluxo de Caixa 2026 CTR]] -> 1.4.1.INVESTIMENTO CDBORE RCP TXFL | C10: =MARÇO!C344 -> 0 | D10: =IF(C10=0,"0,00%",C10/$C$2) -> 0,00% | G10: 8
B11: =Fluxo_de_Caixa_Janeiro[[#This Row],[Fluxo de Caixa 2026 CTR]] -> 1.5 - ITAU C.C.98671-6 MATRIZ | C11: =MARÇO!C345 -> 95802.27 | D11: =IF(C11=0,"0,00%",C11/$C$2) -> 0.21892879 | G11: 9
B12: =Fluxo_de_Caixa_Janeiro[[#This Row],[Fluxo de Caixa 2026 CTR]] -> 1.5.03. ITAU C.C 83290-2 GARANTIDA | C12: =MARÇO!C346 -> 0 | D12: =IF(C12=0,"0,00%",C12/$C$2) -> 0,00% | G12: 10
B13: =Fluxo_de_Caixa_Janeiro[[#This Row],[Fluxo de Caixa 2026 CTR]] -> 1.9 - CONTA PERDA/ROUBO/BONIFICAÇÃO E DOAÇÃO | C13: =MARÇO!C347 -> -20953.13 | D13: =IF(C13=0,"0,00%",C13/$C$2) -> -0.047882408 | G13: 11
B14: =Fluxo_de_Caixa_Janeiro[[#This Row],[Fluxo de Caixa 2026 CTR]] -> 0 | C14: =MARÇO!C348 -> 0 | D14: =IF(C14=0,"0,00%",C14/$C$2) -> 0,00% | G14: 12 | I14: =I20-H34-I34-J34 -> -353624.95
B15: =Fluxo_de_Caixa_Janeiro[[#This Row],[Fluxo de Caixa 2026 CTR]] -> 2.1 - BANCO DO BRASIL C.C.60638-3 FILIAL PALMAS | C15: =MARÇO!C349 -> 33375.7 | D15: =IF(C15=0,"0,00%",C15/$C$2) -> 0.076270652 | G15: 13
B16: =Fluxo_de_Caixa_Janeiro[[#This Row],[Fluxo de Caixa 2026 CTR]] -> 0 | C16: =MARÇO!C350 -> 0 | D16: =IF(C16=0,"0,00%",C16/$C$2) -> 0,00% | G16: 14
B17: =Fluxo_de_Caixa_Janeiro[[#This Row],[Fluxo de Caixa 2026 CTR]] -> 0 | C17: =MARÇO!C351 -> 0 | D17: =IF(C17=0,"0,00%",C17/$C$2) -> 0,00% | G17: 15 | I17: 316630.68
B18: =Fluxo_de_Caixa_Janeiro[[#This Row],[Fluxo de Caixa 2026 CTR]] -> 2.4 - ITAU C.C.98669-0 FILIAL PALMAS | C18: =MARÇO!C352 -> 37.73 | D18: =IF(C18=0,"0,00%",C18/$C$2) -> 8.6221163e-05 | E18: =#REF! -> #REF! | G18: 16
B19: =Fluxo_de_Caixa_Janeiro[[#This Row],[Fluxo de Caixa 2026 CTR]] -> 2.9 - CONTA PERDA/ROUBO E BONIFICAÇÃO FILIAL | C19: =MARÇO!C353 -> -8598.58 | D19: =IF(C19=0,"0,00%",C19/$C$2) -> -0.019649604 | E19: =#REF! -> #REF! | G19: 17
B20: =Fluxo_de_Caixa_Janeiro[[#This Row],[Fluxo de Caixa 2026 CTR]] -> 4.0 - TESOURARIA FILIAL PORTO | C20: =MARÇO!C354 -> 534.16 | D20: =IF(C20=0,"0,00%",C20/$C$2) -> 0.0012206705 | E20: =#REF! -> #REF! | G20: 18
B21: =Fluxo_de_Caixa_Janeiro[[#This Row],[Fluxo de Caixa 2026 CTR]] -> 4.1 - BANCO DO BRASIL C.C.61105-0 FILIAL PORTO | C21: =MARÇO!C355 -> 521.92 | D21: =IF(C21=0,"0,00%",C21/$C$2) -> 0.0011926994 | E21: =#REF! -> #REF! | G21: 19
B22: =Fluxo_de_Caixa_Janeiro[[#This Row],[Fluxo de Caixa 2026 CTR]] -> 0 | C22: =MARÇO!C356 -> 0 | D22: =IF(C22=0,"0,00%",C22/$C$2) -> 0,00% | E22: =#REF! -> #REF! | G22: 20
B23: =Fluxo_de_Caixa_Janeiro[[#This Row],[Fluxo de Caixa 2026 CTR]] -> 4.4 - MERCADO PAGO PIX FILIAL PORTO | C23: =MARÇO!C357 -> 13187.1 | D23: =IF(C23=0,"0,00%",C23/$C$2) -> 0.030135359 | E23: =#REF! -> #REF! | G23: 21
B24: =Fluxo_de_Caixa_Janeiro[[#This Row],[Fluxo de Caixa 2026 CTR]] -> 4.9 - CONTA PERDA/ROUBO E BONIFICAÇÃO FILIAL | C24: =MARÇO!C358 -> -29071.86 | D24: =IF(C24=0,"0,00%",C24/$C$2) -> -0.066435452 | E24: =#REF! -> #REF! | G24: 22
B25: =Fluxo_de_Caixa_Janeiro[[#This Row],[Fluxo de Caixa 2026 CTR]] -> 91.CARTÃO ENDERED 5099+4596+6933+8072 - ESCRITORIO | C25: =MARÇO!C359 -> 4229.69 | D25: =IF(C25=0,"0,00%",C25/$C$2) -> 0.0096657512 | E25: =#REF! -> #REF! | G25: 23
B26: =Fluxo_de_Caixa_Janeiro[[#This Row],[Fluxo de Caixa 2026 CTR]] -> 0 | C26: =MARÇO!C361 -> 220.66 | D26: =IF(C26=0,"0,00%",C26/$C$2) -> 0.00050425555 | E26: =#REF! -> #REF! | G26: 24
B27: =Fluxo_de_Caixa_Janeiro[[#This Row],[Fluxo de Caixa 2026 CTR]] -> Total Receitas Operacionais / Vendas | C27: =SUBTOTAL(109,C29:C51) -> 1009247 | D27: =IFERROR(C27/C332,"") -> 0.99891127 | E27: 0.88526119 | H27: =H28+I28+J28 -> 1009247
A28: 1.1. Receita com Vendas | B28: =Fluxo_de_Caixa_Janeiro[[#This Row],[Fluxo de Caixa 2026 CTR]] -> 1.1. Receita com Vendas | C28: =SUBTOTAL(109,C29:C47) -> 1009247 | D28: =SUM(D29:D47) -> 0.99891127 | E28: 0.88251933 | G28: =C361 -> 250.32 | H28: =SUM(H29:H36) -> 46278.25 | I28: =SUM(I29:I36) -> 606271.08 | J28: =SUM(J29:J36) -> 356697.67
B29: =Fluxo_de_Caixa_Janeiro[[#This Row],[Fluxo de Caixa 2026 CTR]] -> 1.1.01. Receita em Dinheiro | C29: =H29+I29+J29 -> 3589.4 | D29: =IF(C29=0,"0,00%",C29/$C$332) -> 0.0035526408 | E29: 0.079252981 | F29: =IF(Fluxo_de_Caixa_Janeiro34591171012151619[[#This Row],[% ACUMULADO DEZ/2026]]>=Fluxo_de_Caixa_Janeiro34591171012151619[[#This Row],[% Acum no Ano Comparação]],"Verd","Fals") -> Verd | H29: 150 | I29: 3264.41 | J29: 174.99
B30: =Fluxo_de_Caixa_Janeiro[[#This Row],[Fluxo de Caixa 2026 CTR]] -> 1.1.01. Receita em Cartão (Crédito e Débito) | C30: =H30+I30+J30 -> 160565.41 | D30: =IF(C30=0,"0,00%",C30/$C$332) -> 0.15892105 | E30: 0.092740536 | F30: =IF(Fluxo_de_Caixa_Janeiro34591171012151619[[#This Row],[% ACUMULADO DEZ/2026]]>=Fluxo_de_Caixa_Janeiro34591171012151619[[#This Row],[% Acum no Ano Comparação]],"Verd","Fals") -> Verd | H30: 0 | I30: 89019.06 | J30: 71546.35
B31: =Fluxo_de_Caixa_Janeiro[[#This Row],[Fluxo de Caixa 2026 CTR]] -> 1.1.01. Receita de Cheque A Vista | C31: =H31+I31+J31 -> 19225.74 | D31: =IF(C31=0,"0,00%",C31/$C$332) -> 0.019028849 | E31: 0.00028628486 | F31: =IF(Fluxo_de_Caixa_Janeiro34591171012151619[[#This Row],[% ACUMULADO DEZ/2026]]>=Fluxo_de_Caixa_Janeiro34591171012151619[[#This Row],[% Acum no Ano Comparação]],"Verd","Fals") -> Verd | I31: 19225.74
B32: =Fluxo_de_Caixa_Janeiro[[#This Row],[Fluxo de Caixa 2026 CTR]] -> 1.1.01. Receita de Cheque Pré | C32: 0 | D32: =IF(C32=0,"0,00%",C32/$C$332) -> 0,00% | E32: 0.0063111634 | F32: =IF(Fluxo_de_Caixa_Janeiro34591171012151619[[#This Row],[% ACUMULADO DEZ/2026]]>=Fluxo_de_Caixa_Janeiro34591171012151619[[#This Row],[% Acum no Ano Comparação]],"Verd","Fals") -> Verd
B33: =Fluxo_de_Caixa_Janeiro[[#This Row],[Fluxo de Caixa 2026 CTR]] -> 1.1.01. Recebimento de Carteira (Notinha) | C33: =H33+I33+J33 -> 30464 | D33: =IF(C33=0,"0,00%",C33/$C$332) -> 0.030152017 | E33: 0.0001318638 | F33: =IF(Fluxo_de_Caixa_Janeiro34591171012151619[[#This Row],[% ACUMULADO DEZ/2026]]>=Fluxo_de_Caixa_Janeiro34591171012151619[[#This Row],[% Acum no Ano Comparação]],"Verd","Fals") -> Verd | H33: 30464 | I33: 0
B34: =Fluxo_de_Caixa_Janeiro[[#This Row],[Fluxo de Caixa 2026 CTR]] -> 1.1.01. Recebimento de Boletos | C34: =H34+I34+J34 -> 353624.95 | D34: =IF(C34=0,"0,00%",C34/$C$332) -> 0.35000346 | E34: 0.66745712 | F34: =IF(Fluxo_de_Caixa_Janeiro34591171012151619[[#This Row],[% ACUMULADO DEZ/2026]]>=Fluxo_de_Caixa_Janeiro34591171012151619[[#This Row],[% Acum no Ano Comparação]],"Verd","Fals") -> Verd | H34: 14934.25 | I34: 194961.89 | J34: 143728.81
B35: =Fluxo_de_Caixa_Janeiro[[#This Row],[Fluxo de Caixa 2026 CTR]] -> 1.1.01. Recebimento em Depósito e Dep. PIX | C35: =H35+I35+J35 -> 441777.5 | D35: =IF(C35=0,"0,00%",C35/$C$332) -> 0.43725324 | E35: 0.036171198 | F35: =IF(Fluxo_de_Caixa_Janeiro34591171012151619[[#This Row],[% ACUMULADO DEZ/2026]]>=Fluxo_de_Caixa_Janeiro34591171012151619[[#This Row],[% Acum no Ano Comparação]],"Verd","Fals") -> Verd | H35: 730 | I35: 299799.98 | J35: 141247.52
B36: =Fluxo_de_Caixa_Janeiro[[#This Row],[Fluxo de Caixa 2026 CTR]] -> 1.1.02. Recebimento Cheque Devolvido | C36: =H36+I36+J36 -> 0 | D36: =IF(C36=0,"0,00%",C36/$C$332) -> 0,00% | E36: 0.00016817802 | F36: =IF(Fluxo_de_Caixa_Janeiro34591171012151619[[#This Row],[% ACUMULADO DEZ/2026]]>=Fluxo_de_Caixa_Janeiro34591171012151619[[#This Row],[% Acum no Ano Comparação]],"Verd","Fals") -> Verd
B37: =Fluxo_de_Caixa_Janeiro[[#This Row],[Fluxo de Caixa 2026 CTR]] -> 0 | D37: =IF(C37=0,"0,00%",C37/$C$332) -> 0,00% | E37: =#REF! -> #REF! | F37: =IF(Fluxo_de_Caixa_Janeiro34591171012151619[[#This Row],[% ACUMULADO DEZ/2026]]>=Fluxo_de_Caixa_Janeiro34591171012151619[[#This Row],[% Acum no Ano Comparação]],"Verd","Fals") -> #REF!
B38: =Fluxo_de_Caixa_Janeiro[[#This Row],[Fluxo de Caixa 2026 CTR]] -> 0 | D38: =IF(C38=0,"0,00%",C38/$C$332) -> 0,00% | E38: =#REF! -> #REF! | F38: =IF(Fluxo_de_Caixa_Janeiro34591171012151619[[#This Row],[% ACUMULADO DEZ/2026]]>=Fluxo_de_Caixa_Janeiro34591171012151619[[#This Row],[% Acum no Ano Comparação]],"Verd","Fals") -> #REF!
B39: =Fluxo_de_Caixa_Janeiro[[#This Row],[Fluxo de Caixa 2026 CTR]] -> 0 | D39: =IF(C39=0,"0,00%",C39/$C$332) -> 0,00% | E39: =#REF! -> #REF! | F39: =IF(Fluxo_de_Caixa_Janeiro34591171012151619[[#This Row],[% ACUMULADO DEZ/2026]]>=Fluxo_de_Caixa_Janeiro34591171012151619[[#This Row],[% Acum no Ano Comparação]],"Verd","Fals") -> #REF!
B40: =Fluxo_de_Caixa_Janeiro[[#This Row],[Fluxo de Caixa 2026 CTR]] -> 0 | D40: =IF(C40=0,"0,00%",C40/$C$332) -> 0,00% | E40: =#REF! -> #REF! | F40: =IF(Fluxo_de_Caixa_Janeiro34591171012151619[[#This Row],[% ACUMULADO DEZ/2026]]>=Fluxo_de_Caixa_Janeiro34591171012151619[[#This Row],[% Acum no Ano Comparação]],"Verd","Fals") -> #REF!
...

Sheet MAIO
B1: Fluxo de Caixa 2026 CTR | C1: MAIO | D1: % ACUMULADO MAI/2026 | E1: % Acum no Ano Comparação | H1: Matriz | I1: Filia Porto | J1: Filia Palmas
